<?xml version="1.0" encoding="utf-8"?>
<!-- =================================================================================== -->
<!-- |    This document was autogenerated by xacro from Igor_knee.urdf.xacro           | -->
<!-- |    EDITING THIS FILE BY HAND IS NOT RECOMMENDED                                 | -->
<!-- =================================================================================== -->
<robot name="igor">
  <!-- Gazebo plug-in for ROS -->
  <gazebo>
    <plugin filename="libgazebo_ros_control.so" name="gazebo_ros_control">
      <robotNamespace>/igor</robotNamespace>
    </plugin>
  </gazebo>
  <!-- Dummy link for reference -->
  <link name="base_link"/>
  <link name="chassis">
    <inertial>
      <origin rpy="0.0 0.0 0.0" xyz="0 0 0"/>
      <mass value="5.0"/>
      <inertia ixx="0.0774" ixy="0.000" ixz="0.00000" iyy="0.04543" iyz="0.000" izz="0.04543"/>
    </inertial>
    <!-- Mass change for uncertainity-->
    <!--inertial>
     			<origin xyz="0 0 0" rpy="0.0 0.0 0.0" />
			<mass value="4" />
      			<inertia izz="0.036344" iyz="0.0" ixz="0.00" iyy="0.036344" ixy="0.000" ixx="0.061936" />
		</inertial-->
    <visual>
      <origin rpy="3.14159 0.0 -1.570795" xyz="0.0635 0.16 0.1524"/>
      <geometry>
        <!--box size="0.30 0.1 0.30"/-->
        <mesh filename="package://igor/meshes/IgorBody.STL" scale="0.001 0.001 0.001"/>
      </geometry>
      <material name="white">
        <color rgba="1 1 1 1.0"/>
      </material>
    </visual>
    <collision>
      <geometry>
        <box size="0.127 0.3048 0.3048"/>
      </geometry>
    </collision>
  </link>
  <joint name="base_link_to_chassis" type="fixed">
    <origin rpy="0 0 0" xyz="0 0 0"/>
    <parent link="base_link"/>
    <child link="chassis"/>
  </joint>
  <gazebo reference="chassis">
    <mu1 value="1.0"/>
    <mu2 value="1.0"/>
    <kp value="10000.0"/>
    <kd value="10000.0"/>
    <material>Gazebo/Grey</material>
  </gazebo>
  <!-- imu_link for getting data in imu frame -->
  <link name="body_imu_link"/>
  <joint name="body_imu_link_to_chassis" type="fixed">
    <origin rpy="0 0 0" xyz="0 0 0"/>
    <parent link="chassis"/>
    <child link="body_imu_link"/>
  </joint>
  <link name="L_baseActuator">
    <visual>
      <origin rpy="4.712385 3.14159 0" xyz="0.055 -0.0225 -0.0365"/>
      <geometry>
        <mesh filename="package://igor/meshes/X8-Export.STL" scale="0.001 0.001 0.001"/>
      </geometry>
      <material name="red">
        <color rgba="1.0 0.0 0.0 1.0"/>
      </material>
    </visual>
    <collision>
      <origin rpy="0.0 0.0 0.0" xyz="0.0 0.0 0.0"/>
      <geometry>
        <box size="0.11 0.045 0.073"/>
      </geometry>
    </collision>
    <inertial>
      <mass value="0.46"/>
      <inertia ixx="0.00066" ixy="0.0" ixz="0.0" iyy="0.00054" iyz="0.0" izz="0.00028"/>
    </inertial>
  </link>
  <gazebo reference="L_baseActuator">
    <mu1 value="1.0"/>
    <mu2 value="1.0"/>
    <kp value="10000.0"/>
    <kd value="10000.0"/>
    <material>Gazebo/Red</material>
  </gazebo>
  <joint name="L_baseActuator_joint" type="fixed">
    <parent link="chassis"/>
    <child link="L_baseActuator"/>
    <origin rpy="0 0 0" xyz="0.0 0.1749 0"/>
  </joint>
  <gazebo reference="L_baseActuator_joint">
    <preserveFixedJoint>true</preserveFixedJoint>
  </gazebo>
  <link name="R_baseActuator">
    <visual>
      <origin rpy="1.570795 3.14159 0" xyz="0.055 0.0225 0.0365"/>
      <geometry>
        <mesh filename="package://igor/meshes/X8-Export.STL" scale="0.001 0.001 0.001"/>
      </geometry>
      <material name="red">
        <color rgba="1.0 0.0 0.0 1.0"/>
      </material>
    </visual>
    <collision>
      <origin rpy="0.0 0.0 0.0" xyz="0.0 0.0 0.0"/>
      <geometry>
        <box size="0.11 0.045 0.073"/>
      </geometry>
    </collision>
    <inertial>
      <mass value="0.46"/>
      <inertia ixx="0.00066" ixy="0.0" ixz="0.0" iyy="0.00054" iyz="0.0" izz="0.00028"/>
    </inertial>
  </link>
  <gazebo reference="R_baseActuator">
    <mu1 value="1.0"/>
    <mu2 value="1.0"/>
    <kp value="10000.0"/>
    <kd value="10000.0"/>
    <material>Gazebo/Red</material>
  </gazebo>
  <joint name="R_baseActuator_joint" type="fixed">
    <parent link="chassis"/>
    <child link="R_baseActuator"/>
    <origin rpy="0 0 0" xyz="0.0 -0.1749 0.0"/>
  </joint>
  <gazebo reference="R_baseActuator_joint">
    <preserveFixedJoint>true</preserveFixedJoint>
  </gazebo>
  <!--Right Leg-->
  <link name="R_upperleg">
    <visual>
      <origin rpy="-1.570795 1.570795 3.14159" xyz="-0.03175 0.047625 0.0238125"/>
      <geometry>
        <mesh filename="package://igor/meshes/upperLeg.STL" scale="0.001 0.001 0.001"/>
        <!--cylinder radius="0.015875" length="0.35" /-->
      </geometry>
      <material name="white">
        <color rgba="1.0 1.0 1.0 1.0"/>
      </material>
    </visual>
    <collision>
      <origin rpy="0.0 0.0 0.0" xyz="0.0 0.0 -0.175"/>
      <geometry>
        <cylinder length="0.35" radius="0.015875"/>
      </geometry>
    </collision>
    <inertial>
      <origin rpy="0 0 0" xyz="0 0 -0.175"/>
      <mass value="0.22"/>
      <inertia ixx="0.00226" ixy="0.0" ixz="0.0" iyy="0.00226" iyz="0.0" izz="4.6E-05"/>
    </inertial>
  </link>
  <joint name="R_hfe_joint" type="revolute">
    <origin rpy="0 0 0" xyz="0.015875 -0.038375 0.0"/>
    <parent link="R_baseActuator"/>
    <child link="R_upperleg"/>
    <limit effort="15" lower="-0" upper="0" velocity="10"/>
    <axis xyz="0 1 0"/>
    <dynamics damping="0.1"/>
  </joint>
  <transmission name="R_hfe_trans">
    <type>transmission_interface/SimpleTransmission</type>
    <actuator name="R_hfe_motor">
      <mechanicalReduction>1</mechanicalReduction>
    </actuator>
    <joint name="R_hfe_joint">
      <hardwareInterface>hardware_interface/EffortJointInterface</hardwareInterface>
    </joint>
  </transmission>
  <gazebo reference="R_upperleg">
    <mu1 value="1.0"/>
    <mu2 value="1.0"/>
    <kp value="10000.0"/>
    <kd value="10000.0"/>
    <material>Gazebo/White</material>
  </gazebo>
  <!-- IMU Sensor -->
  <!-- imu_link for getting data in imu frame -->
  <!--link name="${prefix}_upperLeg_imu_link"/>

		<joint name="${prefix}_upperLeg_imu_link_to_${prefix}_upperleg" type="fixed">
			<origin xyz="0 0 -${upper_leg_length/2}" rpy="0 0 0" />
			<parent link="${prefix}_upperleg" />
			<child link="${prefix}_upperLeg_imu_link" />
		</joint>

		<gazebo reference="${prefix}_upperleg">
		    <gravity>true</gravity>
		    <sensor name="{prefix}_upperLeg_imu" type="imu">
		      <always_on>true</always_on>
		      <visualize>true</visualize>
		      <!topic>__default_topic__</topic>
		      <plugin filename="libgazebo_ros_imu_sensor.so" name="imu_plugin">
			<robotNamespace>/igor</robotNamespace>
			<topicName>${prefix}_upperLeg_imu/data</topicName>
			<bodyName>${prefix}_upperleg</bodyName>
			<updateRateHZ>500.0</updateRateHZ>
			<gaussianNoise>0.0</gaussianNoise>
			<xyzOffset>0 0 0</xyzOffset>
			<rpyOffset>0 0 0</rpyOffset>
			<frameName>${prefix}_upperLeg_imu_link</frameName>
		      </plugin>
		      <pose>0 0 0 0 0 0</pose>
		    </sensor>
		</gazebo-->
  <link name="R_lowerleg">
    <visual>
      <origin rpy="1.570795 1.570795 3.14159" xyz="0.0396875 -0.03175 0.0486666666667"/>
      <geometry>
        <mesh filename="package://igor/meshes/lowerLeg.STL" scale="0.001 0.001 0.001"/>
        <!--cylinder radius="0.03175" length="0.3" /-->
      </geometry>
      <material name="white"/>
    </visual>
    <collision>
      <origin rpy="0.0 0.0 0.0" xyz="0.0 0.0 -0.15"/>
      <geometry>
        <cylinder length="0.3" radius="0.015875"/>
        <!-- Actual dimensions -->
      </geometry>
    </collision>
    <inertial>
      <origin rpy="0.0 0.0 0.0" xyz="0.0 0.0 -0.15"/>
      <mass value="0.2"/>
      <inertia ixx="0.001521" ixy="0.00" ixz="0.00" iyy="0.001521" iyz="0.000" izz="4.2E-05"/>
    </inertial>
  </link>
  <joint name="R_kfe_joint" type="revolute">
    <origin rpy="0 0 0" xyz="0.01905 0.038375 0.0"/>
    <parent link="R_kneeActuator"/>
    <child link="R_lowerleg"/>
    <limit effort="15" lower="0" upper="0" velocity="10"/>
    <axis xyz="0 1 0"/>
    <dynamics damping="0.1"/>
  </joint>
  <transmission name="R_kfe_trans">
    <type>transmission_interface/SimpleTransmission</type>
    <actuator name="R_kfe_motor">
      <!--hardwareInterface>hardware_interface/EffortJointInterface</hardwareInterface-->
      <mechanicalReduction>1</mechanicalReduction>
    </actuator>
    <joint name="R_kfe_joint">
      <hardwareInterface>hardware_interface/EffortJointInterface</hardwareInterface>
    </joint>
  </transmission>
  <gazebo reference="R_lowerleg">
    <mu1 value="1.0"/>
    <mu2 value="1.0"/>
    <kp value="10000.0"/>
    <kd value="10000.0"/>
    <material>Gazebo/Grey</material>
  </gazebo>
  <!-- IMU Sensor -->
  <!-- imu_link for getting data in imu frame -->
  <!--link name="${prefix}_lowerLeg_imu_link"/>

		<joint name="${prefix}_lowerLeg_imu_link_to_${prefix}_lowerleg" type="fixed">
			<origin xyz="0 0 -${lower_leg_length/2}" rpy="0 0 0" />
			<parent link="${prefix}_lowerleg" />
			<child link="${prefix}_lowerLeg_imu_link" />
		</joint>

		<gazebo reference="${prefix}_lowerleg">
		    <gravity>true</gravity>
		    <sensor name="{prefix}_lowerLeg_imu" type="imu">
		      <always_on>true</always_on>
		      <visualize>true</visualize>
		      <!topic>__default_topic__</topic>
		      <plugin filename="libgazebo_ros_imu_sensor.so" name="imu_plugin">
			<robotNamespace>/igor</robotNamespace>
			<topicName>${prefix}_lowerLeg_imu/data</topicName>
			<bodyName>${prefix}_lowerleg</bodyName>
			<updateRateHZ>500.0</updateRateHZ>
			<gaussianNoise>0.0</gaussianNoise>
			<xyzOffset>0 0 0</xyzOffset>
			<rpyOffset>0 0 0</rpyOffset>
			<frameName>${prefix}_lowerLeg_imu_link</frameName>
		      </plugin>
		      <pose>0 0 0 0 0 0</pose>
		    </sensor>
		</gazebo-->
  <!--Left Leg-->
  <link name="L_upperleg">
    <visual>
      <origin rpy="-1.570795 1.570795 0.0" xyz="0.03175 -0.047625 0.0238125"/>
      <geometry>
        <mesh filename="package://igor/meshes/upperLeg.STL" scale="0.001 0.001 0.001"/>
        <!--cylinder radius="0.015875" length="0.35" /-->
      </geometry>
      <material name="white">
        <color rgba="1.0 1.0 1.0 1.0"/>
      </material>
    </visual>
    <collision>
      <origin rpy="0.0 0.0 0.0" xyz="0.0 0.0 -0.175"/>
      <geometry>
        <cylinder length="0.35" radius="0.015875"/>
      </geometry>
    </collision>
    <inertial>
      <origin rpy="0 0 0" xyz="0 0 -0.175"/>
      <mass value="0.22"/>
      <inertia ixx="0.00226" ixy="0.0" ixz="0.0" iyy="0.00226" iyz="0.0" izz="4.6E-05"/>
    </inertial>
  </link>
  <joint name="L_hfe_joint" type="revolute">
    <origin rpy="0 0 0" xyz="0.015875 0.038375 0.0"/>
    <parent link="L_baseActuator"/>
    <child link="L_upperleg"/>
    <limit effort="15" lower="-0" upper="0" velocity="10"/>
    <axis xyz="0 1 0"/>
    <dynamics damping="0.1"/>
  </joint>
  <transmission name="L_hfe_trans">
    <type>transmission_interface/SimpleTransmission</type>
    <actuator name="L_hfe_motor">
      <mechanicalReduction>1</mechanicalReduction>
    </actuator>
    <joint name="L_hfe_joint">
      <hardwareInterface>hardware_interface/EffortJointInterface</hardwareInterface>
    </joint>
  </transmission>
  <gazebo reference="L_upperleg">
    <mu1 value="1.0"/>
    <mu2 value="1.0"/>
    <kp value="10000.0"/>
    <kd value="10000.0"/>
    <material>Gazebo/White</material>
  </gazebo>
  <!-- IMU Sensor -->
  <!-- imu_link for getting data in imu frame -->
  <!--link name="${prefix}_upperLeg_imu_link"/>

		<joint name="${prefix}_upperLeg_imu_link_to_${prefix}_upperleg" type="fixed">
			<origin xyz="0 0 -${upper_leg_length/2}" rpy="0 0 0" />
			<parent link="${prefix}_upperleg" />
			<child link="${prefix}_upperLeg_imu_link" />
		</joint>

		<gazebo reference="${prefix}_upperleg">
		    <gravity>true</gravity>
		    <sensor name="{prefix}_upperLeg_imu" type="imu">
		      <always_on>true</always_on>
		      <visualize>true</visualize>
		      <!topic>__default_topic__</topic>
		      <plugin filename="libgazebo_ros_imu_sensor.so" name="imu_plugin">
			<robotNamespace>/igor</robotNamespace>
			<topicName>${prefix}_upperLeg_imu/data</topicName>
			<bodyName>${prefix}_upperleg</bodyName>
			<updateRateHZ>500.0</updateRateHZ>
			<gaussianNoise>0.0</gaussianNoise>
			<xyzOffset>0 0 0</xyzOffset>
			<rpyOffset>0 0 0</rpyOffset>
			<frameName>${prefix}_upperLeg_imu_link</frameName>
		      </plugin>
		      <pose>0 0 0 0 0 0</pose>
		    </sensor>
		</gazebo-->
  <link name="L_lowerleg">
    <visual>
      <origin rpy="1.570795 1.570795 0.0" xyz="-0.0396875 0.03175 0.0486666666667"/>
      <geometry>
        <mesh filename="package://igor/meshes/lowerLeg.STL" scale="0.001 0.001 0.001"/>
        <!--cylinder radius="0.03175" length="0.3" /-->
      </geometry>
      <material name="white"/>
    </visual>
    <collision>
      <origin rpy="0.0 0.0 0.0" xyz="0.0 0.0 -0.15"/>
      <geometry>
        <cylinder length="0.3" radius="0.015875"/>
        <!-- Actual dimensions -->
      </geometry>
    </collision>
    <inertial>
      <origin rpy="0.0 0.0 0.0" xyz="0.0 0.0 -0.15"/>
      <mass value="0.2"/>
      <inertia ixx="0.001521" ixy="0.00" ixz="0.00" iyy="0.001521" iyz="0.000" izz="4.2E-05"/>
    </inertial>
  </link>
  <joint name="L_kfe_joint" type="revolute">
    <origin rpy="0 0 0" xyz="0.01905 -0.038375 0.0"/>
    <parent link="L_kneeActuator"/>
    <child link="L_lowerleg"/>
    <limit effort="15" lower="0" upper="0" velocity="10"/>
    <axis xyz="0 1 0"/>
    <dynamics damping="0.1"/>
  </joint>
  <transmission name="L_kfe_trans">
    <type>transmission_interface/SimpleTransmission</type>
    <actuator name="L_kfe_motor">
      <!--hardwareInterface>hardware_interface/EffortJointInterface</hardwareInterface-->
      <mechanicalReduction>1</mechanicalReduction>
    </actuator>
    <joint name="L_kfe_joint">
      <hardwareInterface>hardware_interface/EffortJointInterface</hardwareInterface>
    </joint>
  </transmission>
  <gazebo reference="L_lowerleg">
    <mu1 value="1.0"/>
    <mu2 value="1.0"/>
    <kp value="10000.0"/>
    <kd value="10000.0"/>
    <material>Gazebo/Grey</material>
  </gazebo>
  <!-- IMU Sensor -->
  <!-- imu_link for getting data in imu frame -->
  <!--link name="${prefix}_lowerLeg_imu_link"/>

		<joint name="${prefix}_lowerLeg_imu_link_to_${prefix}_lowerleg" type="fixed">
			<origin xyz="0 0 -${lower_leg_length/2}" rpy="0 0 0" />
			<parent link="${prefix}_lowerleg" />
			<child link="${prefix}_lowerLeg_imu_link" />
		</joint>

		<gazebo reference="${prefix}_lowerleg">
		    <gravity>true</gravity>
		    <sensor name="{prefix}_lowerLeg_imu" type="imu">
		      <always_on>true</always_on>
		      <visualize>true</visualize>
		      <!topic>__default_topic__</topic>
		      <plugin filename="libgazebo_ros_imu_sensor.so" name="imu_plugin">
			<robotNamespace>/igor</robotNamespace>
			<topicName>${prefix}_lowerLeg_imu/data</topicName>
			<bodyName>${prefix}_lowerleg</bodyName>
			<updateRateHZ>500.0</updateRateHZ>
			<gaussianNoise>0.0</gaussianNoise>
			<xyzOffset>0 0 0</xyzOffset>
			<rpyOffset>0 0 0</rpyOffset>
			<frameName>${prefix}_lowerLeg_imu_link</frameName>
		      </plugin>
		      <pose>0 0 0 0 0 0</pose>
		    </sensor>
		</gazebo-->
  <!--Right knee-->
  <link name="R_kneeActuator">
    <visual>
      <origin rpy="1.570795 3.14159 0" xyz="0.055 0.0225 0.0365"/>
      <geometry>
        <mesh filename="package://igor/meshes/X8-Export.STL" scale="0.001 0.001 0.001"/>
      </geometry>
      <material name="red">
        <color rgba="1.0 0.0 0.0 1.0"/>
      </material>
    </visual>
    <collision>
      <origin rpy="0.0 0.0 0.0" xyz="0.0 0.0 0.0"/>
      <geometry>
        <box size="0.11 0.045 0.073"/>
      </geometry>
    </collision>
    <inertial>
      <mass value="0.46"/>
      <inertia ixx="0.00066" ixy="0.0" ixz="0.0" iyy="0.00054" iyz="0.0" izz="0.00028"/>
    </inertial>
  </link>
  <gazebo reference="R_kneeActuator">
    <mu1 value="1.0"/>
    <mu2 value="1.0"/>
    <kp value="10000.0"/>
    <kd value="10000.0"/>
    <material>Gazebo/Red</material>
  </gazebo>
  <joint name="R_kneeActuator_joint" type="fixed">
    <parent link="R_upperleg"/>
    <child link="R_kneeActuator"/>
    <origin rpy="0 0 0" xyz="-0.01905 0.038375 -0.374333333333"/>
  </joint>
  <gazebo reference="R_kneeActuator_joint">
    <preserveFixedJoint>true</preserveFixedJoint>
  </gazebo>
  <!--Left knee-->
  <link name="L_kneeActuator">
    <visual>
      <origin rpy="4.712385 3.14159 0" xyz="0.055 -0.0225 -0.0365"/>
      <geometry>
        <mesh filename="package://igor/meshes/X8-Export.STL" scale="0.001 0.001 0.001"/>
      </geometry>
      <material name="red">
        <color rgba="1.0 0.0 0.0 1.0"/>
      </material>
    </visual>
    <collision>
      <origin rpy="0.0 0.0 0.0" xyz="0.0 0.0 0.0"/>
      <geometry>
        <box size="0.11 0.045 0.073"/>
      </geometry>
    </collision>
    <inertial>
      <mass value="0.46"/>
      <inertia ixx="0.00066" ixy="0.0" ixz="0.0" iyy="0.00054" iyz="0.0" izz="0.00028"/>
    </inertial>
  </link>
  <gazebo reference="L_kneeActuator">
    <mu1 value="1.0"/>
    <mu2 value="1.0"/>
    <kp value="10000.0"/>
    <kd value="10000.0"/>
    <material>Gazebo/Red</material>
  </gazebo>
  <joint name="L_kneeActuator_joint" type="fixed">
    <parent link="L_upperleg"/>
    <child link="L_kneeActuator"/>
    <origin rpy="0 0 0" xyz="-0.01905 -0.038375 -0.374333333333"/>
  </joint>
  <gazebo reference="L_kneeActuator_joint">
    <preserveFixedJoint>true</preserveFixedJoint>
  </gazebo>
  <!--Right wheel-->
  <link name="R_wheelActuator">
    <visual>
      <origin rpy="1.570795 3.14159 0" xyz="0.055 0.0225 0.0365"/>
      <geometry>
        <mesh filename="package://igor/meshes/X8-Export.STL" scale="0.001 0.001 0.001"/>
      </geometry>
      <material name="red">
        <color rgba="1.0 0.0 0.0 1.0"/>
      </material>
    </visual>
    <collision>
      <origin rpy="0.0 0.0 0.0" xyz="0.0 0.0 0.0"/>
      <geometry>
        <box size="0.11 0.045 0.073"/>
      </geometry>
    </collision>
    <inertial>
      <mass value="0.46"/>
      <inertia ixx="0.00066" ixy="0.0" ixz="0.0" iyy="0.00054" iyz="0.0" izz="0.00028"/>
    </inertial>
  </link>
  <gazebo reference="R_wheelActuator">
    <mu1 value="1.0"/>
    <mu2 value="1.0"/>
    <kp value="10000.0"/>
    <kd value="10000.0"/>
    <material>Gazebo/Red</material>
  </gazebo>
  <joint name="R_wheelActuator_joint" type="fixed">
    <parent link="R_lowerleg"/>
    <child link="R_wheelActuator"/>
    <origin rpy="0 0 0" xyz="-0.015875 -0.0412 -0.3292"/>
  </joint>
  <gazebo reference="R_wheelActuator_joint">
    <preserveFixedJoint>true</preserveFixedJoint>
  </gazebo>
  <link name="R_wheel">
    <visual>
      <geometry>
        <mesh filename="package://igor/meshes/wheel.STL" scale="0.001 0.001 0.001"/>
      </geometry>
      <origin rpy="0 0 0.0" xyz="-0.1016 -0.1066 -0.1016"/>
      <material name="white">
        <color rgba="1.0 1.0 1.0 1.0"/>
      </material>
    </visual>
    <collision>
      <geometry>
        <cylinder length="0.03" radius="0.1016"/>
      </geometry>
      <origin rpy="1.570795 0 0" xyz="0 0 0"/>
    </collision>
    <inertial>
      <mass value="0.35"/>
      <inertia ixx="0.000929" ixy="0.0" ixz="0.0" iyy="0.001806" iyz="0.0" izz="0.000929"/>
    </inertial>
    <!--inertial>
	      			<mass value="0.28"/>
	      			<inertia iyy="0.001445" ixy="0.0" ixz="0.0" ixx="0.000744" iyz="0.0" izz="0.000744"/>
	    		</inertial-->
  </link>
  <gazebo reference="R_wheel">
    <mu1 value="1e+20"/>
    <!--For ground friction, large value means no slip-->
    <mu2 value="1e+20"/>
    <kp value="1e+10"/>
    <!--HOW HARD IS SURFACE (contact stiffness), higher value means harder-->
    <kd value="1.0"/>
    <minDepth>0.001</minDepth>
    <material>Gazebo/Grey</material>
  </gazebo>
  <joint name="R_wheel_joint" type="continuous">
    <origin rpy="0 0 0" xyz="0.02 -0.0375 0.0"/>
    <parent link="R_wheelActuator"/>
    <child link="R_wheel"/>
    <limit effort="5" velocity="30"/>
    <!-- effort limit in N (prismatic) or N.m (revolute), Velocity limit in m/s or rad/s -->
    <axis xyz="0 1 0"/>
    <joint_properties damping="0.1" friction="0.0"/>
  </joint>
  <!--transmission name="Diff_${prefix}_wheel_trans">
	      		<type>transmission_interface/SimpleTransmission</type>
	      		<actuator name="${prefix}_wheel_motor">
				<mechanicalReduction>1</mechanicalReduction>
	      		</actuator>
	      		<joint name="${prefix}_wheel_joint">
				<hardwareInterface>hardware_interface/VelocityJointInterface</hardwareInterface>
	      		</joint>
    		</transmission-->
  <transmission name="R_wheel_trans">
    <type>transmission_interface/SimpleTransmission</type>
    <actuator name="R_wheel_motor">
      <mechanicalReduction>1</mechanicalReduction>
    </actuator>
    <joint name="R_wheel_joint">
      <hardwareInterface>hardware_interface/EffortJointInterface</hardwareInterface>
    </joint>
  </transmission>
  <!-- Enable the Joint Feedback -->
  <gazebo reference="R_wheel_joint">
    <provideFeedback>true</provideFeedback>
  </gazebo>
  <!-- The force_torque_sensor plugin -->
  <!--gazebo>
		<plugin name="ft_sensor" filename="libgazebo_ros_ft_sensor.so">
		<updateRate>1000.0</updateRate>
		<topicName>${prefix}_wheel_ft_sensor</topicName>
		<jointName>${prefix}_wheel_joint</jointName>
		</plugin>
		</gazebo-->
  <!--Left wheel-->
  <link name="L_wheelActuator">
    <visual>
      <origin rpy="4.712385 3.14159 0" xyz="0.055 -0.0225 -0.0365"/>
      <geometry>
        <mesh filename="package://igor/meshes/X8-Export.STL" scale="0.001 0.001 0.001"/>
      </geometry>
      <material name="red">
        <color rgba="1.0 0.0 0.0 1.0"/>
      </material>
    </visual>
    <collision>
      <origin rpy="0.0 0.0 0.0" xyz="0.0 0.0 0.0"/>
      <geometry>
        <box size="0.11 0.045 0.073"/>
      </geometry>
    </collision>
    <inertial>
      <mass value="0.46"/>
      <inertia ixx="0.00066" ixy="0.0" ixz="0.0" iyy="0.00054" iyz="0.0" izz="0.00028"/>
    </inertial>
  </link>
  <gazebo reference="L_wheelActuator">
    <mu1 value="1.0"/>
    <mu2 value="1.0"/>
    <kp value="10000.0"/>
    <kd value="10000.0"/>
    <material>Gazebo/Red</material>
  </gazebo>
  <joint name="L_wheelActuator_joint" type="fixed">
    <parent link="L_lowerleg"/>
    <child link="L_wheelActuator"/>
    <origin rpy="0 0 0" xyz="-0.015875 0.0412 -0.3292"/>
  </joint>
  <gazebo reference="L_wheelActuator_joint">
    <preserveFixedJoint>true</preserveFixedJoint>
  </gazebo>
  <link name="L_wheel">
    <visual>
      <geometry>
        <mesh filename="package://igor/meshes/wheel.STL" scale="0.001 0.001 0.001"/>
      </geometry>
      <origin rpy="0 0 3.14159" xyz="0.1016 0.1066 -0.1016"/>
      <material name="white">
        <color rgba="1.0 1.0 1.0 1.0"/>
      </material>
    </visual>
    <collision>
      <geometry>
        <cylinder length="0.03" radius="0.1016"/>
      </geometry>
      <origin rpy="1.570795 0 0" xyz="0 0 0"/>
    </collision>
    <inertial>
      <mass value="0.35"/>
      <inertia ixx="0.000929" ixy="0.0" ixz="0.0" iyy="0.001806" iyz="0.0" izz="0.000929"/>
    </inertial>
    <!--inertial>
	      			<mass value="0.28"/>
	      			<inertia iyy="0.001445" ixy="0.0" ixz="0.0" ixx="0.000744" iyz="0.0" izz="0.000744"/>
	    		</inertial-->
  </link>
  <gazebo reference="L_wheel">
    <mu1 value="1e+20"/>
    <!--For ground friction, large value means no slip-->
    <mu2 value="1e+20"/>
    <kp value="1e+10"/>
    <!--HOW HARD IS SURFACE (contact stiffness), higher value means harder-->
    <kd value="1.0"/>
    <minDepth>0.001</minDepth>
    <material>Gazebo/Grey</material>
  </gazebo>
  <joint name="L_wheel_joint" type="continuous">
    <origin rpy="0 0 0" xyz="0.02 0.0375 0.0"/>
    <parent link="L_wheelActuator"/>
    <child link="L_wheel"/>
    <limit effort="5" velocity="30"/>
    <!-- effort limit in N (prismatic) or N.m (revolute), Velocity limit in m/s or rad/s -->
    <axis xyz="0 1 0"/>
    <joint_properties damping="0.1" friction="0.0"/>
  </joint>
  <!--transmission name="Diff_${prefix}_wheel_trans">
	      		<type>transmission_interface/SimpleTransmission</type>
	      		<actuator name="${prefix}_wheel_motor">
				<mechanicalReduction>1</mechanicalReduction>
	      		</actuator>
	      		<joint name="${prefix}_wheel_joint">
				<hardwareInterface>hardware_interface/VelocityJointInterface</hardwareInterface>
	      		</joint>
    		</transmission-->
  <transmission name="L_wheel_trans">
    <type>transmission_interface/SimpleTransmission</type>
    <actuator name="L_wheel_motor">
      <mechanicalReduction>1</mechanicalReduction>
    </actuator>
    <joint name="L_wheel_joint">
      <hardwareInterface>hardware_interface/EffortJointInterface</hardwareInterface>
    </joint>
  </transmission>
  <!-- Enable the Joint Feedback -->
  <gazebo reference="L_wheel_joint">
    <provideFeedback>true</provideFeedback>
  </gazebo>
  <!-- The force_torque_sensor plugin -->
  <!--gazebo>
		<plugin name="ft_sensor" filename="libgazebo_ros_ft_sensor.so">
		<updateRate>1000.0</updateRate>
		<topicName>${prefix}_wheel_ft_sensor</topicName>
		<jointName>${prefix}_wheel_joint</jointName>
		</plugin>
		</gazebo-->
  <!--Robot Center Dummy-->
  <link name="robot_center_link">
    <inertial>
      <origin rpy="0.0 0.0 0.0" xyz="0 0 0"/>
      <mass value="1e-3"/>
      <inertia ixx="0.000001" ixy="0.0" ixz="0.0" iyy="0.000001" iyz="0.0" izz="0.000001"/>
    </inertial>
    <collision>
      <geometry>
        <box size="0.001 0.001 0.001"/>
      </geometry>
    </collision>
  </link>
  <joint name="actuator_to_robot_center" type="fixed">
    <origin rpy="0 0 0" xyz="0.02 -0.1749 0.0"/>
    <parent link="L_wheelActuator"/>
    <child link="robot_center_link"/>
  </joint>
  <gazebo reference="actuator_to_robot_center">
    <preserveFixedJoint>true</preserveFixedJoint>
  </gazebo>
  <!-- imu_link for getting data in imu frame -->
  <link name="center_imu_link"/>
  <joint name="center_imu_link" type="fixed">
    <origin rpy="0 0 0" xyz="0 0 0"/>
    <parent link="robot_center_link"/>
    <child link="center_imu_link"/>
  </joint>
  <!-- Center IMU Sensor -->
  <gazebo reference="robot_center_link">
    <gravity>true</gravity>
    <sensor name="center_imu" type="imu">
      <always_on>true</always_on>
      <visualize>true</visualize>
      <update_rate>500</update_rate>
      <!--topic>__default_topic__</topic-->
      <plugin filename="libgazebo_ros_imu_sensor.so" name="imu_plugin">
        <robotNamespace>/igor</robotNamespace>
        <topicName>center_imu/data</topicName>
        <bodyName>robot_center_link</bodyName>
        <updateRateHZ>500.0</updateRateHZ>
        <gaussianNoise>0.0</gaussianNoise>
        <xyzOffset>0 0 0</xyzOffset>
        <rpyOffset>0 0 0</rpyOffset>
        <frameName>center_imu_link</frameName>
      </plugin>
      <pose>0 0 0 0 0 0</pose>
    </sensor>
  </gazebo>
  <!-- Odometery Sensor -->
  <gazebo>
    <plugin filename="libgazebo_ros_p3d.so" name="p3d_base_controller">
      <robotNamespace>/igor</robotNamespace>
      <alwaysOn>true</alwaysOn>
      <updateRate>500.0</updateRate>
      <bodyName>base_link</bodyName>
      <topicName>odom</topicName>
      <gaussianNoise>0.0</gaussianNoise>
      <frameName>map</frameName>
      <xyzOffsets>0 0 0</xyzOffsets>
      <rpyOffsets>0 0 0</rpyOffsets>
    </plugin>
  </gazebo>
  <!-- Odometery Sensor -->
  <gazebo>
    <plugin filename="libgazebo_ros_p3d.so" name="p3d_base_controller">
      <robotNamespace>/igor</robotNamespace>
      <alwaysOn>true</alwaysOn>
      <updateRate>500.0</updateRate>
      <bodyName>robot_center_link</bodyName>
      <topicName>center</topicName>
      <gaussianNoise>0.0</gaussianNoise>
      <frameName>map</frameName>
      <xyzOffsets>0 0 0</xyzOffsets>
      <rpyOffsets>0 0 0</rpyOffsets>
    </plugin>
  </gazebo>
  <!-- Body IMU Sensor -->
  <!--gazebo reference="chassis">
	    <gravity>true</gravity>
	    <sensor name="body_imu" type="imu">
	      <always_on>true</always_on>
	      <visualize>true</visualize>
	      <!topic>__default_topic__</topic>
	      <plugin filename="libgazebo_ros_imu_sensor.so" name="imu_plugin">
		<robotNamespace>/igor</robotNamespace>
		<topicName>body_imu/data</topicName>
		<bodyName>chassis</bodyName>
		<updateRateHZ>1000.0</updateRateHZ>
		<gaussianNoise>0.0</gaussianNoise>
		<xyzOffset>0 0 0</xyzOffset>
		<rpyOffset>0 0 0</rpyOffset>
		<frameName>body_imu_link</frameName>
	      </plugin>
	      <pose>0 0 0 0 0 0</pose>
	    </sensor>
	</gazebo-->
</robot>
